Traceback (most recent call last):
  File "/Users/brunamoura/PrevisorReconhecimento/.venv/lib/python3.11/site-packages/jupyter_cache/executors/utils.py", line 58, in single_nb_execution
    executenb(
  File "/Users/brunamoura/PrevisorReconhecimento/.venv/lib/python3.11/site-packages/nbclient/client.py", line 1314, in execute
    return NotebookClient(nb=nb, resources=resources, km=km, **kwargs).execute()
           ^^^^^^^^^^^^^^^^^^^^^^^^^^^^^^^^^^^^^^^^^^^^^^^^^^^^^^^^^^^^^^^^^^^^^
  File "/Users/brunamoura/PrevisorReconhecimento/.venv/lib/python3.11/site-packages/jupyter_core/utils/__init__.py", line 165, in wrapped
    return loop.run_until_complete(inner)
           ^^^^^^^^^^^^^^^^^^^^^^^^^^^^^^
  File "/Users/brunamoura/anaconda3/lib/python3.11/asyncio/base_events.py", line 653, in run_until_complete
    return future.result()
           ^^^^^^^^^^^^^^^
  File "/Users/brunamoura/PrevisorReconhecimento/.venv/lib/python3.11/site-packages/nbclient/client.py", line 709, in async_execute
    await self.async_execute_cell(
  File "/Users/brunamoura/PrevisorReconhecimento/.venv/lib/python3.11/site-packages/nbclient/client.py", line 1062, in async_execute_cell
    await self._check_raise_for_error(cell, cell_index, exec_reply)
  File "/Users/brunamoura/PrevisorReconhecimento/.venv/lib/python3.11/site-packages/nbclient/client.py", line 918, in _check_raise_for_error
    raise CellExecutionError.from_cell_and_msg(cell, exec_reply_content)
nbclient.exceptions.CellExecutionError: An error occurred while executing the following cell:
------------------
#Bibliotecas

import geobr
import matplotlib.pyplot as plt
from matplotlib.ticker import ScalarFormatter
import matplotlib.colors as mcolors
import pandas as pd
import numpy as np
import warnings
import seaborn as sns

#Estilizar conteÃºdo
warnings.filterwarnings('ignore')

pd.set_option('display.max_rows', None)
pd.set_option('display.max_columns', None)
pd.set_option('display.float_format', '{:.2f}'.format)
np.set_printoptions(suppress=True)

def estilo_tabelas(df, max_altura='300px', casas_decimais=3):
    return (
        df.style.set_table_styles(
            [
                {'selector': 'thead th', 'props': [('font-size', '12px'), ('text-align', 'center'), ('border-bottom', '2px solid #007BFF')]},
                {'selector': 'td', 'props': [('font-size', '10px'), ('text-align', 'center'), ('max-height', '40px'), ('white-space', 'nowrap'), ('text-overflow', 'ellipsis'), ('overflow', 'hidden'), ('max-width', '100px')]},
                {'selector': 'tr:nth-child(odd)', 'props': [('background-color', '#ffffff')]},
                {'selector': 'table', 'props': [('width', '90%'), ('margin-left', 'auto'), ('margin-right', 'auto'), ('border-collapse', 'collapse')]},
                {'selector': 'td, th', 'props': [('border', '1px solid #666')]},  # Bordas cinza escuro
            ]
        ).set_properties(
            **{'border-color': 'darkgray', 'border-style': 'solid', 'border-width': '1px'}
        ).set_table_attributes(
            f'style="height:auto; overflow:auto; max-height:{max_altura}; display:block;"'  
        ).format(
            precision=casas_decimais  
        )
    )

# Importar a base de dados

object_columns = ['Protocolo_S2iD', 'Nome_Municipio', 'Sigla_UF', 'regiao',
                  'Setores CensitÃ¡rios', 'Status', 'DH_Descricao', 'DM_Descricao',
                  'DA_Descricao', 'DA_Polui/cont da Ã¡gua', 'DA_Polui/cont do ar',
                  'DA_Polui/cont do solo', 'DA_Dimi/exauri hÃ­drico',
                  "DA_IncÃªndi parques/APA's/APP's", 'PEPL_Descricao', 'PEPR_Descricao',
                  'Categoria', 'Grupo', 'Subgrupo', 'Tipo', 'Subtipo']

dtype = {col: 'object' for col in object_columns}

df_eventos = pd.read_csv(
    "https://raw.githubusercontent.com/brunagmoura/PrevisorReconhecimento/refs/heads/main/df_eventos_desastres_rec_nrec.csv",
    sep=';',
    dtype = dtype,
    decimal=',',
)

estilo_tabelas(df_eventos.head(5))

------------------


[0;31m---------------------------------------------------------------------------[0m
[0;31mModuleNotFoundError[0m                       Traceback (most recent call last)
Cell [0;32mIn[1], line 3[0m
[1;32m      1[0m [38;5;66;03m#Bibliotecas[39;00m
[0;32m----> 3[0m [38;5;28;01mimport[39;00m [38;5;21;01mgeobr[39;00m
[1;32m      4[0m [38;5;28;01mimport[39;00m [38;5;21;01mmatplotlib[39;00m[38;5;21;01m.[39;00m[38;5;21;01mpyplot[39;00m [38;5;28;01mas[39;00m [38;5;21;01mplt[39;00m
[1;32m      5[0m [38;5;28;01mfrom[39;00m [38;5;21;01mmatplotlib[39;00m[38;5;21;01m.[39;00m[38;5;21;01mticker[39;00m [38;5;28;01mimport[39;00m ScalarFormatter

[0;31mModuleNotFoundError[0m: No module named 'geobr'

